F
======================================================================
FAIL: test_running_median (running_median_testSuite.TestRunningMedian.test_running_median)
----------------------------------------------------------------------
Traceback (most recent call last):
  File "/app/running_median_testSuite.py", line 8, in test_running_median
    self.assertEqual(result, [2, 1.5, 2, 3.5, 2, 2, 2])
AssertionError: None != [2, 1.5, 2, 3.5, 2, 2, 2]

----------------------------------------------------------------------
Ran 1 test in 0.008s

FAILED (failures=1)
2
1.5
2
3.5
2
2.0
2
Command exited with non-zero status 1
	Command being timed: "python3 -m unittest discover -s . -p *test*.py"
	User time (seconds): 0.24
	System time (seconds): 0.12
	Percent of CPU this job got: 47%
	Elapsed (wall clock) time (h:mm:ss or m:ss): 0:00.78
	Average shared text size (kbytes): 0
	Average unshared data size (kbytes): 0
	Average stack size (kbytes): 0
	Average total size (kbytes): 0
	Maximum resident set size (kbytes): 14720
	Average resident set size (kbytes): 0
	Major (requiring I/O) page faults: 0
	Minor (reclaiming a frame) page faults: 2489
	Voluntary context switches: 93
	Involuntary context switches: 234
	Swaps: 0
	File system inputs: 0
	File system outputs: 576
	Socket messages sent: 0
	Socket messages received: 0
	Signals delivered: 0
	Page size (bytes): 4096
	Exit status: 1
